{"priority": "major", "kind": "bug", "repository": {"links": {"self": {"href": "data/repositories/levitsky/pyteomics.json"}, "html": {"href": "#!/levitsky/pyteomics"}, "avatar": {"href": "data/bytebucket.org/ravatar/{3f6302de-10da-4d3c-b258-0bb6a2368972}ts=74456"}}, "type": "repository", "name": "pyteomics", "full_name": "levitsky/pyteomics", "uuid": "{3f6302de-10da-4d3c-b258-0bb6a2368972}"}, "links": {"attachments": {"href": "data/repositories/levitsky/pyteomics/issues/40/attachments_page=1.json"}, "self": {"href": "data/repositories/levitsky/pyteomics/issues/40.json"}, "watch": {"href": "https://api.bitbucket.org/2.0/repositories/levitsky/pyteomics/issues/40/watch"}, "comments": {"href": "data/repositories/levitsky/pyteomics/issues/40/comments_page=1.json"}, "html": {"href": "#!/levitsky/pyteomics/issues/40/std-bad_alloc-when-loading-multiple"}, "vote": {"href": "https://api.bitbucket.org/2.0/repositories/levitsky/pyteomics/issues/40/vote"}}, "reporter": null, "title": "std::bad_alloc when loading multiple pyteomics submodules", "component": null, "votes": 0, "watches": null, "content": {"raw": "I'm having a strange error when I'm loading pyteomics biolccc and electrochem together. This only happens when I'm running a python script from the terminal, I have not had it when working in python.\r\n\r\nWhen I run the following script ('tester.py'):\r\n\r\nimport pyteomics.electrochem\r\nimport pyteomics.mass\r\nimport pyteomics.biolccc\r\n\r\nI get the following error:\r\n\r\nterminate called after throwing an instance of 'std::bad_alloc'\r\n  what():  std::bad_alloc\r\nAborted (core dumped)\r\n\r\nThe strange thing is this error only comes up around once out of every 10 times, so if I run:\r\n\r\nfor i in {1..10}; do python tester.py; done\r\n\r\nThen most of the times it will run fine. The one time that it does not work, I can see the memory (%MEM from top) slowly increasing until around 50%, and then I get the std::bad_alloc error message.\r\n\r\nI'm running Ubuntu Bionic Beaver, release 18.04. Any suggestions or ideas for why this might be occurring are greatly appreciated!", "markup": "markdown", "html": "<p>I'm having a strange error when I'm loading pyteomics biolccc and electrochem together. This only happens when I'm running a python script from the terminal, I have not had it when working in python.</p>\n<p>When I run the following script ('tester.py'):</p>\n<p>import pyteomics.electrochem\nimport pyteomics.mass\nimport pyteomics.biolccc</p>\n<p>I get the following error:</p>\n<p>terminate called after throwing an instance of 'std::bad_alloc'\n  what():  std::bad_alloc\nAborted (core dumped)</p>\n<p>The strange thing is this error only comes up around once out of every 10 times, so if I run:</p>\n<p>for i in {1..10}; do python tester.py; done</p>\n<p>Then most of the times it will run fine. The one time that it does not work, I can see the memory (%MEM from top) slowly increasing until around 50%, and then I get the std::bad_alloc error message.</p>\n<p>I'm running Ubuntu Bionic Beaver, release 18.04. Any suggestions or ideas for why this might be occurring are greatly appreciated!</p>", "type": "rendered"}, "assignee": null, "state": "open", "version": null, "edited_on": null, "created_on": "2019-05-28T20:33:36.046148+00:00", "milestone": null, "updated_on": "2019-08-09T22:39:14.193713+00:00", "type": "issue", "id": 40}