{"priority": "major", "kind": "bug", "repository": {"links": {"self": {"href": "data/repositories/levitsky/pyteomics.json"}, "html": {"href": "#!/levitsky/pyteomics"}, "avatar": {"href": "data/bytebucket.org/ravatar/{3f6302de-10da-4d3c-b258-0bb6a2368972}ts=74456"}}, "type": "repository", "name": "pyteomics", "full_name": "levitsky/pyteomics", "uuid": "{3f6302de-10da-4d3c-b258-0bb6a2368972}"}, "links": {"attachments": {"href": "data/repositories/levitsky/pyteomics/issues/48/attachments_page=1.json"}, "self": {"href": "data/repositories/levitsky/pyteomics/issues/48.json"}, "watch": {"href": "https://api.bitbucket.org/2.0/repositories/levitsky/pyteomics/issues/48/watch"}, "comments": {"href": "data/repositories/levitsky/pyteomics/issues/48/comments_page=1.json"}, "html": {"href": "#!/levitsky/pyteomics/issues/48/pepxmldataframe-error"}, "vote": {"href": "https://api.bitbucket.org/2.0/repositories/levitsky/pyteomics/issues/48/vote"}}, "reporter": null, "title": "pepxml.DataFrame error", "component": null, "votes": 0, "watches": null, "content": {"raw": "Hi,\r\nI was trying to read a .pep.xml file by DataFrame, but I constantly got the same error.\r\n\r\nMy code:\r\n\r\n```\r\n#!python\r\n...\r\na=pepxml.read(\"interact.pep.xml\")\r\nb=pepxml.DataFrame(a)\r\n...\r\n```\r\n\r\nError:\r\n\r\n\r\n```\r\n#!\r\n\r\nTraceback (most recent call last):\r\n  File \"InteractPepXMLParser.py\", line 20, in <module>\r\n    b=pepxml.DataFrame(a)\r\n  File \"C:\\Users\\Armin\\AppData\\Local\\Programs\\Python\\Python36\\lib\\site-packages\\pyteomics\\pepxml.py\", line 412, in DataFrame\r\n    return pd.DataFrame(gen_items(), **pd_kwargs)\r\n  File \"C:\\Users\\Armin\\AppData\\Local\\Programs\\Python\\Python36\\lib\\site-packages\\pandas\\core\\frame.py\", line 382, in __init__\r\n    data = list(data)\r\n  File \"C:\\Users\\Armin\\AppData\\Local\\Programs\\Python\\Python36\\lib\\site-packages\\pyteomics\\pepxml.py\", line 406, in gen_items\r\n    info.update(ar['peptideprophet_result']['parameter'])\r\nKeyError: 'parameter'\r\n```\r\n\r\n\r\nThis happened after I changed some of my PeptideProphet settings. (The function works fine for some sort of settings.) I should mention that pepxml.filter works fine in every situation.\r\nCould you please help me?", "markup": "markdown", "html": "<p>Hi,\nI was trying to read a .pep.xml file by DataFrame, but I constantly got the same error.</p>\n<p>My code:</p>\n<div class=\"codehilite language-python\"><pre><span></span><span class=\"o\">...</span>\n<span class=\"n\">a</span><span class=\"o\">=</span><span class=\"n\">pepxml</span><span class=\"o\">.</span><span class=\"n\">read</span><span class=\"p\">(</span><span class=\"s2\">&quot;interact.pep.xml&quot;</span><span class=\"p\">)</span>\n<span class=\"n\">b</span><span class=\"o\">=</span><span class=\"n\">pepxml</span><span class=\"o\">.</span><span class=\"n\">DataFrame</span><span class=\"p\">(</span><span class=\"n\">a</span><span class=\"p\">)</span>\n<span class=\"o\">...</span>\n</pre></div>\n\n\n<p>Error:</p>\n<div class=\"codehilite\"><pre><span></span>Traceback (most recent call last):\n  File &quot;InteractPepXMLParser.py&quot;, line 20, in &lt;module&gt;\n    b=pepxml.DataFrame(a)\n  File &quot;C:\\Users\\Armin\\AppData\\Local\\Programs\\Python\\Python36\\lib\\site-packages\\pyteomics\\pepxml.py&quot;, line 412, in DataFrame\n    return pd.DataFrame(gen_items(), **pd_kwargs)\n  File &quot;C:\\Users\\Armin\\AppData\\Local\\Programs\\Python\\Python36\\lib\\site-packages\\pandas\\core\\frame.py&quot;, line 382, in __init__\n    data = list(data)\n  File &quot;C:\\Users\\Armin\\AppData\\Local\\Programs\\Python\\Python36\\lib\\site-packages\\pyteomics\\pepxml.py&quot;, line 406, in gen_items\n    info.update(ar[&#39;peptideprophet_result&#39;][&#39;parameter&#39;])\nKeyError: &#39;parameter&#39;\n</pre></div>\n\n\n<p>This happened after I changed some of my PeptideProphet settings. (The function works fine for some sort of settings.) I should mention that pepxml.filter works fine in every situation.\nCould you please help me?</p>", "type": "rendered"}, "assignee": null, "state": "resolved", "version": null, "edited_on": null, "created_on": "2019-10-26T21:53:35.370497+00:00", "milestone": null, "updated_on": "2019-10-27T16:15:53.762988+00:00", "type": "issue", "id": 48}