{"links": {"self": {"href": "data/repositories/levitsky/pyteomics/issues/49/comments/56220192.json"}, "html": {"href": "#!/levitsky/pyteomics/issues/49#comment-56220192"}}, "issue": {"links": {"self": {"href": "data/repositories/levitsky/pyteomics/issues/49.json"}}, "type": "issue", "id": 49, "repository": {"links": {"self": {"href": "data/repositories/levitsky/pyteomics.json"}, "html": {"href": "#!/levitsky/pyteomics"}, "avatar": {"href": "data/bytebucket.org/ravatar/{3f6302de-10da-4d3c-b258-0bb6a2368972}ts=74456"}}, "type": "repository", "name": "pyteomics", "full_name": "levitsky/pyteomics", "uuid": "{3f6302de-10da-4d3c-b258-0bb6a2368972}"}, "title": "mzidentml wrong annotation in DataFrame"}, "content": {"raw": "@{557058:bafc7224-b2a9-46b1-9918-153a342c1455} please feel free to update if you are able to reproduce the problem.", "markup": "markdown", "html": "<p><span class=\"ap-mention\" data-atlassian-id=\"557058:bafc7224-b2a9-46b1-9918-153a342c1455\">@Yasset Perez</span> please feel free to update if you are able to reproduce the problem.</p>", "type": "rendered"}, "created_on": "2020-02-18T16:23:47.722608+00:00", "user": {"display_name": "Lev Levitsky", "uuid": "{eb44325f-4ee0-4e0b-a27c-f2ea23122a56}", "links": {"self": {"href": "https://api.bitbucket.org/2.0/users/%7Beb44325f-4ee0-4e0b-a27c-f2ea23122a56%7D"}, "html": {"href": "https://bitbucket.org/%7Beb44325f-4ee0-4e0b-a27c-f2ea23122a56%7D/"}, "avatar": {"href": "data/secure.gravatar.com/avatar/a2593c44c42429c503d2e5e9e307e241d=httpsavatar-management--avatars.us-west-2.prod.public.atl-paas.netinitialsLL-6.png"}}, "nickname": "levitsky", "type": "user", "account_id": "557058:986c547b-c50a-40b3-948a-29b4a93b7b30"}, "updated_on": null, "type": "issue_comment", "id": 56220192}