{"links": {"self": {"href": "data/repositories/levitsky/pyteomics/issues/33/comments/49773136.json"}, "html": {"href": "#!/levitsky/pyteomics/issues/33#comment-49773136"}}, "issue": {"links": {"self": {"href": "data/repositories/levitsky/pyteomics/issues/33.json"}}, "type": "issue", "id": 33, "repository": {"links": {"self": {"href": "data/repositories/levitsky/pyteomics.json"}, "html": {"href": "#!/levitsky/pyteomics"}, "avatar": {"href": "data/bytebucket.org/ravatar/{3f6302de-10da-4d3c-b258-0bb6a2368972}ts=74456"}}, "type": "repository", "name": "pyteomics", "full_name": "levitsky/pyteomics", "uuid": "{3f6302de-10da-4d3c-b258-0bb6a2368972}"}, "title": "Problems w/ creating DataFrame from X!Tandem file"}, "content": {"raw": "Please feel free to reopen if this error occurs with the current version.", "markup": "markdown", "html": "<p>Please feel free to reopen if this error occurs with the current version.</p>", "type": "rendered"}, "created_on": "2019-01-07T15:48:27.113734+00:00", "user": {"display_name": "Lev Levitsky", "uuid": "{eb44325f-4ee0-4e0b-a27c-f2ea23122a56}", "links": {"self": {"href": "https://api.bitbucket.org/2.0/users/%7Beb44325f-4ee0-4e0b-a27c-f2ea23122a56%7D"}, "html": {"href": "https://bitbucket.org/%7Beb44325f-4ee0-4e0b-a27c-f2ea23122a56%7D/"}, "avatar": {"href": "data/secure.gravatar.com/avatar/a2593c44c42429c503d2e5e9e307e241d=httpsavatar-management--avatars.us-west-2.prod.public.atl-paas.netinitialsLL-6.png"}}, "nickname": "levitsky", "type": "user", "account_id": "557058:986c547b-c50a-40b3-948a-29b4a93b7b30"}, "updated_on": null, "type": "issue_comment", "id": 49773136}