{"pagelen": 100, "values": [{"changes": {"content": {"new": "Hello,\r\n\r\nI have run into a problem using tandem.DataFrame() to read an X!Tandem output file.  In particular, a KeyError is raised at the statement near the end of the above mentioned routine at the statement:\r\n\r\n            del protein['peptide']['peptide']\r\n\r\nIf I wrap this in a try block then I hit another KeyError at \r\n\r\n            info['scan'] = item['support']['fragment ion mass spectrum']['note']\r\n\r\nHere is the error message:\r\n\r\n\r\n```\r\nbash-3.2$ ./CuWm_analysis.py -i foo.xml -f 'X!Tandem'\r\nTraceback (most recent call last):\r\n  File \"./CuWm_analysis.py\", line 47, in <module>\r\n    sys.exit(main(ns))\r\n  File \"./CuWm_analysis.py\", line 33, in main\r\n    unprocessed = supported_formats[ns.format].DataFrame(ns.infile)\r\n  File \"/opt/local/Library/Frameworks/Python.framework/Versions/3.6/lib/python3.6/site-packages/pyteomics/tandem.py\", line 310, in DataFrame\r\n    del protein['peptide']['peptide']\r\nKeyError: 'peptide'\r\n```", "old": "Hello,\r\n\r\nI have run into a problem using tandem.DataFrame() to read an X!Tandem output file.  In particular, a KeyError is raised at the statement near the end of the above mentioned routine at the statement:\r\n\r\n            del protein['peptide']['peptide']\r\n\r\nIf I wrap this in a try block then I hit another KeyError at \r\n\r\n            info['scan'] = item['support']['fragment ion mass spectrum']['note']\r\n\r\nHere is the error message:\r\n\r\nbash-3.2$ ./CuWm_analysis.py -i foo.xml -f 'X!Tandem'\r\nTraceback (most recent call last):\r\n  File \"./CuWm_analysis.py\", line 47, in <module>\r\n    sys.exit(main(ns))\r\n  File \"./CuWm_analysis.py\", line 33, in main\r\n    unprocessed = supported_formats[ns.format].DataFrame(ns.infile)\r\n  File \"/opt/local/Library/Frameworks/Python.framework/Versions/3.6/lib/python3.6/site-packages/pyteomics/tandem.py\", line 310, in DataFrame\r\n    del protein['peptide']['peptide']\r\nKeyError: 'peptide'"}, "assignee": {"new": "levitsky", "old": ""}, "assignee_account_id": {"new": "557058:986c547b-c50a-40b3-948a-29b4a93b7b30", "old": ""}}, "links": {"self": {"href": "data/repositories/levitsky/pyteomics/issues/33/changes/48692403.json"}, "html": {"href": "#!/levitsky/pyteomics/issues/33#comment-48692403"}}, "issue": {"links": {"self": {"href": "data/repositories/levitsky/pyteomics/issues/33.json"}}, "type": "issue", "id": 33, "repository": {"links": {"self": {"href": "data/repositories/levitsky/pyteomics.json"}, "html": {"href": "#!/levitsky/pyteomics"}, "avatar": {"href": "data/bytebucket.org/ravatar/{3f6302de-10da-4d3c-b258-0bb6a2368972}ts=74456"}}, "type": "repository", "name": "pyteomics", "full_name": "levitsky/pyteomics", "uuid": "{3f6302de-10da-4d3c-b258-0bb6a2368972}"}, "title": "Problems w/ creating DataFrame from X!Tandem file"}, "created_on": "2018-11-01T23:04:39.067294+00:00", "user": {"display_name": "Lev Levitsky", "uuid": "{eb44325f-4ee0-4e0b-a27c-f2ea23122a56}", "links": {"self": {"href": "https://api.bitbucket.org/2.0/users/%7Beb44325f-4ee0-4e0b-a27c-f2ea23122a56%7D"}, "html": {"href": "https://bitbucket.org/%7Beb44325f-4ee0-4e0b-a27c-f2ea23122a56%7D/"}, "avatar": {"href": "data/secure.gravatar.com/avatar/a2593c44c42429c503d2e5e9e307e241d=httpsavatar-management--avatars.us-west-2.prod.public.atl-paas.netinitialsLL-6.png"}}, "nickname": "levitsky", "type": "user", "account_id": "557058:986c547b-c50a-40b3-948a-29b4a93b7b30"}, "message": {"raw": "(formatted the traceback)", "markup": "markdown", "html": "<p>(formatted the traceback)</p>", "type": "rendered"}, "type": "issue_change", "id": 48692403}, {"changes": {"state": {"new": "resolved", "old": "new"}}, "links": {"self": {"href": "data/repositories/levitsky/pyteomics/issues/33/changes/49773136.json"}, "html": {"href": "#!/levitsky/pyteomics/issues/33#comment-49773136"}}, "issue": {"links": {"self": {"href": "data/repositories/levitsky/pyteomics/issues/33.json"}}, "type": "issue", "id": 33, "repository": {"links": {"self": {"href": "data/repositories/levitsky/pyteomics.json"}, "html": {"href": "#!/levitsky/pyteomics"}, "avatar": {"href": "data/bytebucket.org/ravatar/{3f6302de-10da-4d3c-b258-0bb6a2368972}ts=74456"}}, "type": "repository", "name": "pyteomics", "full_name": "levitsky/pyteomics", "uuid": "{3f6302de-10da-4d3c-b258-0bb6a2368972}"}, "title": "Problems w/ creating DataFrame from X!Tandem file"}, "created_on": "2019-01-07T15:48:27.113734+00:00", "user": {"display_name": "Lev Levitsky", "uuid": "{eb44325f-4ee0-4e0b-a27c-f2ea23122a56}", "links": {"self": {"href": "https://api.bitbucket.org/2.0/users/%7Beb44325f-4ee0-4e0b-a27c-f2ea23122a56%7D"}, "html": {"href": "https://bitbucket.org/%7Beb44325f-4ee0-4e0b-a27c-f2ea23122a56%7D/"}, "avatar": {"href": "data/secure.gravatar.com/avatar/a2593c44c42429c503d2e5e9e307e241d=httpsavatar-management--avatars.us-west-2.prod.public.atl-paas.netinitialsLL-6.png"}}, "nickname": "levitsky", "type": "user", "account_id": "557058:986c547b-c50a-40b3-948a-29b4a93b7b30"}, "message": {"raw": "Please feel free to reopen if this error occurs with the current version.", "markup": "markdown", "html": "<p>Please feel free to reopen if this error occurs with the current version.</p>", "type": "rendered"}, "type": "issue_change", "id": 49773136}], "page": 1, "size": 2}